<?xml version="1.0" ?>

<robot name="espeleo" xmlns:xacro="http://www.ros.org/wiki/xacro">


  <material name="black">
    <color rgba="0.0 0.0 0.0 1.0"/>
  </material>
  <material name="blue">
    <color rgba="0.0 0.0 0.8 1.0"/>
  </material>
  <material name="green">
    <color rgba="0.0 0.8 0.0 1.0"/>
  </material>
  <material name="grey">
    <color rgba="0.2 0.2 0.2 1.0"/>
  </material>
  <material name="orange">
    <color rgba="1.0 0.423529411765 0.0392156862745 1.0"/>
  </material>
  <material name="brown">
    <color rgba="0.870588235294 0.811764705882 0.764705882353 1.0"/>
  </material>
  <material name="red">
    <color rgba="0.8 0.0 0.0 1.0"/>
  </material>
  <material name="white">
    <color rgba="1.0 1.0 1.0 1.0"/>
  </material>

 
  <link name="base_link"/>

  <joint name="base_joint" type="fixed">
    <axis xyz="0 0 0"/>
    <origin rpy="0 0 0" xyz="0 0 .15"/>
    <parent link="base_link"/>
    <child link="chassis"/>
  </joint>


  <link name="chassis">


    <collision>
      <origin rpy="0 0 0" xyz="0 0 0"/>
      <geometry>
        <box size="0.54 0.27 0.145"/>
      </geometry>
    </collision>

    <visual>
      <origin rpy="-1.57079632679 0 0" xyz="-0.283 -0.23 0.0725"/>
      <geometry>
        <mesh filename="package://espeleo_description/urdf/stl/Espeleo-22.STL" scale="0.001 0.001 0.001"/>
      </geometry>
      <material name="white"/>
    </visual>

    <inertial>
      <origin rpy="0 0 0" xyz="0 0 -.05"/>
      <mass value="15.0"/>
      <inertia ixx=".040005110" ixy=".02001773" ixz="-0.00034131" iyy=".17086763" iyz="0.00466448" izz=".16009832"/>
      <!--<inertia ixx="4." ixy="0" ixz="0" iyy="4." iyz="0" izz="4.0151875"/>-->
    </inertial>
  </link>


  <link name="left_front_wheel">

    <collision>
      <origin rpy="1.57079632679 0 0" xyz="0 0 0"/>
      <geometry>
        <cylinder length="0.043" radius="0.14"/>
      </geometry>
    </collision>

    <visual>
      <origin rpy="0 0 0" xyz="0 0 0"/>
      <geometry>
        <mesh filename="package://espeleo_description/urdf/stl/roda_esquerda.stl"/>
      </geometry>
      <material name="grey"/>
    </visual>

    <inertial>
      <origin rpy="1.57079632679 0 0" xyz="0 0 0"/>
      <mass value="0.8"/>
      <inertia ixx="0.000895020" ixy="-0.000001" ixz="-0.000000" iyy="0.000895023" iyz="-0.000000" izz=".001758982"/>
    </inertial>
  </link>
  
  <joint name="left_front_wheel_joint" type="continuous"> <!--type="revolute">-->
    <parent link="chassis"/>
    <child link="left_front_wheel"/>
    <origin rpy="0 0 0" xyz="0.215 0.175 -0.01"/>
    <axis rpy="0 0 0" xyz="0 1 0"/>
    <!--<limit command_effort="100" current="10" effort="80" gear_velocity="10" lower="-9.42" upper="9.42" velocity="15"/>-->
    <joint_properties damping="0.0" friction="0.0"/>
  </joint>

  <transmission name="left_front_trans">
    <type>transmission_interface/SimpleTransmission</type>
    <joint name="left_front_wheel_joint">
      <EffortJointInterface>EffortJointInterface</EffortJointInterface>
    </joint>
    <actuator name="left_frontMotor">
      <EffortJointInterface>EffortJointInterface</EffortJointInterface>
      <mechanicalReduction>10</mechanicalReduction>
    </actuator>
  </transmission>



  <!--<link name="left_middle_wheel">

    <collision>
      <origin rpy="1.57079632679 0 0" xyz="0 0 0"/>
      <geometry>
        <cylinder length="0.043" radius="0.14"/>
      </geometry>
    </collision>

    <visual>
      <origin rpy="0 0 0" xyz="0 0 0"/>
      <geometry>
        <mesh filename="package://espeleo_description/urdf/stl/roda_esquerda.stl"/>
      </geometry>
      <material name="grey"/>
    </visual>

    <inertial>
      <origin rpy="1.57079632679 0 0" xyz="0 0 0"/>
      <mass value="0.2"/>
      <inertia ixx="0.00101081666667" ixy="0" ixz="0" iyy="0.00101081666667" iyz="0" izz="0.00196"/>
    </inertial>
  </link>

  <joint name="left_middle_wheel_joint" type="revolute">
    <parent link="chassis"/>
    <child link="left_middle_wheel"/>
    <origin rpy="0 0 0" xyz="0.0 0.225 -0.01"/>
    <axis rpy="0 0 0" xyz="0 1 0"/>
    <limit command_effort="100" current="10" effort="80" gear_velocity="10" lower="-9.42" upper="9.42" velocity="15"/> 
    <joint_properties damping="0.0" friction="0.0"/>
  </joint>

  <transmission name="left_middle_trans">
    <type>transmission_interface/SimpleTransmission</type>
    <joint name="left_middle_wheel_joint">
      <EffortJointInterface>hardware_interface/EffortJointInterface</EffortJointInterface>
    </joint>
    <actuator name="left_middleMotor">
      <EffortJointInterface>hardware_interface/EffortJointInterface</EffortJointInterface>
      <mechanicalReduction>10</mechanicalReduction>
    </actuator>
  </transmission>-->



  <link name="left_back_wheel">

    <collision>
      <origin rpy="1.57079632679 0 0" xyz="0 0 0"/>
      <geometry>
        <cylinder length="0.043" radius="0.14"/>
      </geometry>
    </collision>

    <visual>
      <origin rpy="0 0 0" xyz="0 0 0"/>
      <geometry>
        <mesh filename="package://espeleo_description/urdf/stl/roda_esquerda.stl"/>
      </geometry>
      <material name="grey"/>
    </visual>

    <inertial>
      <origin rpy="1.57079632679 0 0" xyz="0 0 0"/>
      <mass value="0.8"/>
      <inertia ixx="0.000895020" ixy="-0.000001" ixz="-0.000000" iyy="0.000895023" iyz="-0.000000" izz=".001758982"/>
    </inertial>
  </link>
  
  <joint name="left_back_wheel_joint" type="continuous"> <!--type="revolute">-->
    <parent link="chassis"/>
    <child link="left_back_wheel"/>
    <origin rpy="0 0 0" xyz="-0.212 0.175 -0.01"/>
    <axis rpy="0 0 0" xyz="0 1 0"/>
    <!--<limit command_effort="100" current="10" effort="80" gear_velocity="10" lower="-9.42" upper="9.42" velocity="15"/>-->
    <joint_properties damping="0.0" friction="0.0"/>
  </joint>

  <transmission name="left_back_trans">
    <type>transmission_interface/SimpleTransmission</type>
    <joint name="left_back_wheel_joint">
      <EffortJointInterface>EffortJointInterface</EffortJointInterface>
    </joint>
    <actuator name="left_backMotor">
      <EffortJointInterface>EffortJointInterface</EffortJointInterface>
      <mechanicalReduction>10</mechanicalReduction>
    </actuator>
  </transmission>


  <link name="right_front_wheel">

    <collision>
      <origin rpy="1.57079632679 0 0" xyz="0 0 0"/>
      <geometry>
        <cylinder length="0.043" radius="0.14"/>
      </geometry>
    </collision>

    <visual>
      <origin rpy="0 0 3.14159265359" xyz="0 0 0"/>
      <geometry>
        <mesh filename="package://espeleo_description/urdf/stl/roda_esquerda.stl"/>
      </geometry>
      <material name="grey"/>
    </visual>

    <inertial>
      <origin rpy="1.57079632679 0 0" xyz="0 0 0"/>
      <mass value="0.8"/>
      <inertia ixx="0.000895020" ixy="-0.000001" ixz="-0.000000" iyy="0.000895023" iyz="-0.000000" izz=".001758982"/>
    </inertial>
  </link>
  
  <joint name="right_front_wheel_joint" type="continuous"> <!--type="revolute">-->
    <parent link="chassis"/>
    <child link="right_front_wheel"/>
    <origin rpy="0 0 0" xyz="0.215 -0.175 -0.01"/>
    <axis rpy="0 0 0" xyz="0 1 0"/>
    <!--<limit command_effort="100" current="10" effort="80" gear_velocity="10" lower="-9.42" upper="9.42" velocity="15"/>-->
    <joint_properties damping="0.0" friction="0.0"/>
  </joint>

  <transmission name="right_front_trans">
    <type>transmission_interface/SimpleTransmission</type>
    <joint name="right_front_wheel_joint">
      <EffortJointInterface>EffortJointInterface</EffortJointInterface>
    </joint>
    <actuator name="right_frontMotor">
      <EffortJointInterface>EffortJointInterface</EffortJointInterface>
      <mechanicalReduction>10</mechanicalReduction>
    </actuator>
  </transmission>


 <!-- <link name="right_middle_wheel">

    <collision>
      <origin rpy="1.57079632679 0 0" xyz="0 0 0"/>
      <geometry>
        <cylinder length="0.043" radius="0.14"/>
      </geometry>
    </collision>

    <visual>
      <origin rpy="3.1415 0 3.14159265359" xyz="0 0 0"/>
      <geometry>
        <mesh filename="package://espeleo_description/urdf/stl/roda_esquerda.stl"/>
      </geometry>
      <material name="grey"/>
    </visual>

    <inertial>
      <origin rpy="1.57079632679 0 0" xyz="0 0 0"/>
      <mass value="0.2"/>
      <inertia ixx="0.00101081666667" ixy="0" ixz="0" iyy="0.00101081666667" iyz="0" izz="0.00196"/>
    </inertial>
  </link>
  
  <joint name="right_middle_wheel_joint" type="revolute">
    <parent link="chassis"/>
    <child link="right_middle_wheel"/>
    <origin rpy="3.1415 0 0" xyz="0 -0.225 -0.01"/>
    <axis rpy="0 0 0" xyz="0 1 0"/>
    <limit command_effort="100" current="10" effort="80" gear_velocity="10" lower="-9.42" upper="9.42" velocity="15"/> 
    <joint_properties damping="0.0" friction="0.0"/>
  </joint>

  <transmission name="right_middle_trans">
    <type>transmission_interface/SimpleTransmission</type>
    <joint name="right_middle_wheel_joint">
      <EffortJointInterface>hardware_interface/EffortJointInterface</EffortJointInterface>
    </joint>
    <actuator name="right_middleMotor">
      <EffortJointInterface>hardware_interface/EffortJointInterface</EffortJointInterface>
      <mechanicalReduction>10</mechanicalReduction>
    </actuator>
  </transmission>-->


  <link name="right_back_wheel">

    <collision>
      <origin rpy="1.57079632679 0 0" xyz="0 0 0"/>
      <geometry>
        <cylinder length="0.043" radius="0.14"/>
      </geometry>
    </collision>

    <visual>
      <origin rpy="0 0 3.14159265359" xyz="0 0 0"/>
      <geometry>
        <mesh filename="package://espeleo_description/urdf/stl/roda_esquerda.stl"/>
      </geometry>
      <material name="grey"/>
    </visual>

    <inertial>
      <origin rpy="1.57079632679 0 0" xyz="0 0 0"/>
      <mass value="0.8"/>
      <inertia ixx="0.000895020" ixy="-0.000001" ixz="-0.000000" iyy="0.000895023" iyz="-0.000000" izz=".001758982"/>
    </inertial>
  </link>
  
  <joint name="right_back_wheel_joint" type="continuous"> <!--type="revolute">-->
    <parent link="chassis"/>
    <child link="right_back_wheel"/>
    <origin rpy="0 0 0" xyz="-0.212 -0.175 -0.01"/>
    <axis rpy="0 0 0" xyz="0 1 0"/>
    <!--<limit command_effort="100" current="10" effort="80" gear_velocity="10" lower="-9.42" upper="9.42" velocity="15"/> -->
    <joint_properties damping="0.0" friction="0.0"/>
  </joint>

  <transmission name="right_back_trans">
    <type>transmission_interface/SimpleTransmission</type>
    <joint name="right_back_wheel_joint">
      <EffortJointInterface>EffortJointInterface</EffortJointInterface>
    </joint>
    <actuator name="right_backMotor">
      <EffortJointInterface>EffortJointInterface</EffortJointInterface>
      <mechanicalReduction>10</mechanicalReduction>
    </actuator>
  </transmission>


  <!-- sensor_tower -->


  <link name="sensor_tower">

    <collision>
      <origin rpy="0 0 0" xyz="0 0 0.109"/>
      <geometry>
        <box size="0.19 0.19 0.18"/>
      </geometry>
    </collision>

    <visual>
      <origin rpy="1.57079632679 0 0" xyz="-0.08 0.2 0"/>
      <geometry>
        <mesh filename="package://espeleo_description/urdf/stl/Torre.STL" scale="0.001 0.001 0.001"/>
      </geometry>
      <material name="grey"/>
    </visual>

    <inertial>
      <origin rpy="0 0 0" xyz="0 0 0"/>
      <mass value="0.2"/>
      <inertia ixx="1e-6" ixy="0" ixz="0" iyy="1e-6" iyz="0" izz="1e-6"/>
    </inertial>
  </link>

  <joint name="sensor_tower_joint" type="fixed">
    <axis xyz="0 1 0"/>
    <origin rpy="0 0 0" xyz="0 0 .055"/>
    <parent link="chassis"/>
    <child link="sensor_tower"/>
  </joint>

  <!-- Caso necessite utilizar a TF da IMU na torre altere o parent link para (<parent link="chassis"/>) e utilize as seguintes coordenadas de origin (<origin rpy="0 0 0" xyz="-0.025 -0.015 .087"/>) -->


  <!-- Imu --> 

  <link name="imu_link">
  <inertial>
      <origin rpy="0 0 0" xyz="0 0 0"/>
      <mass value="0.05"/>
      <inertia ixx="1e-6" ixy="0" ixz="0" iyy="1e-6" iyz="0" izz="1e-6"/>
    </inertial>
  </link>

  <joint name="imu_joint" type="fixed">
    <axis xyz="0 1 0"/>
    <origin rpy="0 0 0" xyz="0.1275 -0.0175 0.0445"/> 
    <parent link="chassis"/>
    <child link="imu_link"/>
  </joint>
  

  <!-- Laser Lidar -->
  

  <link name="os1_sensor">

    <collision>
      <origin rpy="0 0 0" xyz="0 0 0.045"/>
      <geometry>
        <box size="0.13 0.13 0.095"/>
      </geometry>
    </collision>

    <visual>
      <origin rpy="1.57079632679 0 1.57079632679" xyz="-0.09 -0.054 -0.01"/>
      <geometry>
        <mesh filename="package://espeleo_description/urdf/stl/Lidar.STL" scale="0.001 0.001 0.001"/>
      </geometry>
      <material name="orange"/>
    </visual>

    <inertial>
        <origin rpy="0 0 0" xyz="0 0 0"/>
        <mass value="0.5"/>
        <inertia ixx="1e-6" ixy="0" ixz="0" iyy="1e-6" iyz="0" izz="1e-6"/>
      </inertial>
    </link>

  <joint name="laser_joint" type="fixed">
    <axis xyz="0 0 0"/>
    <origin rpy="0 0 0" xyz="0 0 .205"/>
    <parent link="sensor_tower"/>
    <child link="os1_sensor"/>
  </joint>




  <!-- Camera D435i simulada -->
  

  <!--
  <link name="d435i_sim_link">
  <inertial>
      <origin rpy="0 0 0" xyz="0 0 0"/>
      <mass value="0.01"/>
      <inertia ixx="1e-6" ixy="0" ixz="0" iyy="1e-6" iyz="0" izz="1e-6"/>
    </inertial>
    </link>
  
  <joint name="realsense_d435_sim_joint" type="fixed">
    <axis xyz="0 0 0"/>
     <origin rpy="0 0 3.1415" xyz="0 0 0"/> 
    <parent link="sensor_tower"/>
    <child link="d435i_sim_link"/>
  </joint>-->

<!-- Gazebo -->

  <gazebo reference="base_link">
    <material>Gazebo/White</material>
  </gazebo>
  
  <!--<gazebo>
    <plugin name="differential_drive_controller" filename="libgazebo_ros_diff_drive.so">
      <alwaysOn>false</alwaysOn>
      <legacyMode>false</legacyMode>
      <updateRate>20</updateRate>
      <leftJoint>left_front_wheel_joint</leftJoint>
      <rightJoint>right_front_wheel_joint</rightJoint>
      <wheelSeparation>0.3</wheelSeparation>
      <wheelDiameter>0.28</wheelDiameter>
      <torque>20</torque>
      <commandTopic>/cmd_vel</commandTopic>
      <odometryTopic>/espeleo/odom</odometryTopic>
      <odometryFrame>odom</odometryFrame>
      <robotBaseFrame>base_link</robotBaseFrame>
    </plugin>
  </gazebo>-->
  <gazebo>
  <plugin name="skid_steer_drive_controller" filename="libgazebo_ros_skid_steer_drive.so">
    <updateRate>50.0</updateRate>
    <robotNamespace>espeleo</robotNamespace>
    <leftFrontJoint>left_front_wheel_joint</leftFrontJoint>
    <rightFrontJoint>right_front_wheel_joint</rightFrontJoint>
    <leftRearJoint>left_back_wheel_joint</leftRearJoint>
    <rightRearJoint>right_back_wheel_joint</rightRearJoint>
    <wheelSeparation>0.35</wheelSeparation>
    <wheelDiameter>0.28</wheelDiameter>
    <commandTopic>cmd_vel</commandTopic>
    <odometryTopic>odom</odometryTopic>,
    <odometryFrame>odom</odometryFrame>
    <robotBaseFrame>base_link</robotBaseFrame>
    <torque>1000</torque>
    <topicName>cmd_vel</topicName>
    <broadcastTF>false</broadcastTF>
  </plugin>
</gazebo>
 

  <!--<gazebo>
    <plugin name="gazebo_ros_control" filename="libgazebo_ros_control.so">
      <robotNamespace>espeleo</robotNamespace>
      <robotSimType>gazebo_ros_control/DefaultRobotHWSim</robotSimType>
      <legacyModeNS>true</legacyModeNS>
    </plugin>
  </gazebo>
-->
  <!--<gazebo>
    <plugin filename="libdiffdrive_plugin_multi_wheel.so" name="diffdrive_plugin_multiwheel">
      <alwaysOn>true</alwaysOn>
      <updateRate>100.0</updateRate>
      <leftJoints>left_front_wheel_joint left_back_wheel_joint</leftJoints>
      <rightJoints>right_front_wheel_joint right_back_wheel_joint</rightJoints>-->
      <!-- <wheelSeparation>${chassisWidth+wheelWidth}</wheelSeparation> THis is the right one, but the robot takes too much time to turn -->
      <!--<wheelSeparation>1</wheelSeparation>-->
     <!-- <wheelDiameter>0.28</wheelDiameter>
      <torque>1000000</torque>
      <position name="position_iface_2"/>
      <robotBaseFrame>base_link</robotBaseFrame>
      <commandTopic>/cmd_vel</commandTopic>
      <publishOdometryTf>1</publishOdometryTf>
      <publishOdometryMsg>1</publishOdometryMsg>
    </plugin>
  </gazebo>-->

  <!--
  <gazebo reference="camera">
    <material>Gazebo/Green</material>
    <sensor name="camera1" type="camera">
      <update_rate>30.0</update_rate>
      <camera name="head">
        <horizontal_fov>1.3962634</horizontal_fov>
        <image>
          <width>800</width>
          <height>800</height>
          <format>R8G8B8</format>
        </image>
        <clip>
          <near>0.02</near>
          <far>300</far>
        </clip>
      </camera>
      <plugin filename="libgazebo_ros_camera.so" name="camera_controller">
        <alwaysOn>true</alwaysOn>
        <updateRate>0.0</updateRate>
        <cameraName>espeleo/camera1</cameraName>
        <imageTopicName>image_raw</imageTopicName>
        <cameraInfoTopicName>camera_info</cameraInfoTopicName>
        <frameName>camera</frameName>
        <hackBaseline>0.07</hackBaseline>
        <distortionK1>0.0</distortionK1>
        <distortionK2>0.0</distortionK2>
        <distortionK3>0.0</distortionK3>
        <distortionT1>0.0</distortionT1>
        <distortionT2>0.0</distortionT2>
      </plugin>
    </sensor>
  </gazebo>-->

  <!-- hokuyo -->
  <gazebo reference="hokuyo">
    <sensor name="head_hokuyo_sensor" type="ray">
      <pose>0 0 0 0 0 0</pose>
      <visualize>false</visualize>
      <update_rate>40</update_rate>
      <ray>
        <scan>
          <horizontal>
            <samples>720</samples>
            <resolution>1</resolution>
            <min_angle>-1.570796</min_angle>
            <max_angle>1.570796</max_angle>
          </horizontal>
        </scan>
        <range>
          <min>0.20</min>
          <max>30.0</max>
          <resolution>0.01</resolution>
        </range>
        <noise>
          <type>gaussian</type>
          <!-- Noise parameters based on published spec for Hokuyo laser

               achieving "+-30mm" accuracy at range < 10m.  A mean of 0.0m and

               stddev of 0.01m will put 99.7% of samples within 0.03m of the true

               reading. -->
          <mean>0.0</mean>
          <stddev>0.01</stddev>
        </noise>
      </ray>
      <plugin filename="libgazebo_ros_laser.so" name="gazebo_ros_head_hokuyo_controller">
        <topicName>/espeleo/laser/scan</topicName>
        <frameName>os1_sensor</frameName>
      </plugin>
    </sensor>
  </gazebo>

<gazebo reference="left_front_wheel">
    <mu1 value="1"/>
    <mu2 value="1"/>
    <kp value="1000000.0"/>
    <kd value="10.0"/>
    <fdir1 value="0 0 1"/>
    <minDepth>0.001</minDepth>
    <maxContacts>1</maxContacts>
    <!--maxVel>1.0</maxVel-->
    <material>Gazebo/DarkGrey</material>
  </gazebo>

<!--<gazebo reference="left_middle_wheel">
    <mu1 value="1"/>
    <mu2 value="1"/>
    <kp value="1000000.0"/>
    <kd value="10.0"/>
    <fdir1 value="0 0 1"/>
    <minDepth>0.001</minDepth>
    <maxContacts>1</maxContacts>
    maxVel>1.0</maxVel
    <material>Gazebo/DarkGrey</material>
</gazebo>-->

<gazebo reference="left_back_wheel">
    <mu1 value="1"/>
    <mu2 value="1"/>
    <kp value="1000000.0"/>
    <kd value="10.0"/>
    <fdir1 value="0 0 1"/>
    <minDepth>0.001</minDepth>
    <maxContacts>1</maxContacts>
    <!--maxVel>1.0</maxVel-->
    <material>Gazebo/DarkGrey</material>
  </gazebo>


<gazebo reference="right_front_wheel">
    <mu1 value="1"/>
    <mu2 value="1"/>
    <kp value="1000000.0"/>
    <kd value="10.0"/>
    <fdir1 value="0 0 1"/>
    <minDepth>0.001</minDepth>
    <maxContacts>1</maxContacts>
    <!--maxVel>1.0</maxVel-->
    <material>Gazebo/DarkGrey</material>
</gazebo>
<!--
<gazebo reference="right_middle_wheel">
    <mu1 value="1"/>
    <mu2 value="1"/>
    <kp value="1000000.0"/>
    <kd value="10.0"/>
    <fdir1 value="0 0 1"/>
    <minDepth>0.001</minDepth>
    <maxContacts>1</maxContacts>
    <material>Gazebo/DarkGrey</material>
  </gazebo>-->

<gazebo reference="right_back_wheel">
    <mu1 value="1"/>
    <mu2 value="1"/>
    <kp value="1000000.0"/>
    <kd value="10.0"/>
    <fdir1 value="0 0 1"/>
    <minDepth>0.001</minDepth>
    <maxContacts>1</maxContacts>
    <!--maxVel>1.0</maxVel-->
    <material>Gazebo/DarkGrey</material>
  </gazebo>

<gazebo reference="sensor_tower">
    <material>Gazebo/DarkGrey</material>
</gazebo>

<gazebo reference="os1_sensor">
  <material>Gazebo/Grey</material>
</gazebo>

</robot>
